
About to train for 20 epochs
 ** On entry to SGEMM  parameter number 10 had an illegal value
Traceback (most recent call last):
  File "/home/lts5-ts/Documents/ahmed/bmai_ahmed/demo_bmai.py", line 52, in <module>
    main(args)
  File "/home/lts5-ts/Documents/ahmed/bmai_ahmed/demo_bmai.py", line 44, in main
    mean_training_loss = trainer.train(args.epochs)
  File "/home/lts5-ts/Documents/ahmed/bmai_ahmed/trainer_bmai_2.py", line 168, in train
    scores = model(imgs)
  File "/home/lts5-ts/anaconda3/envs/pycolo/lib/python3.9/site-packages/torch/nn/modules/module.py", line 1051, in _call_impl
    return forward_call(*input, **kwargs)
  File "/home/lts5-ts/anaconda3/envs/pycolo/lib/python3.9/site-packages/torchvision/models/mobilenetv2.py", line 200, in forward
    return self._forward_impl(x)
  File "/home/lts5-ts/anaconda3/envs/pycolo/lib/python3.9/site-packages/torchvision/models/mobilenetv2.py", line 196, in _forward_impl
    x = self.classifier(x)
  File "/home/lts5-ts/anaconda3/envs/pycolo/lib/python3.9/site-packages/torch/nn/modules/module.py", line 1051, in _call_impl
    return forward_call(*input, **kwargs)
  File "/home/lts5-ts/anaconda3/envs/pycolo/lib/python3.9/site-packages/torch/nn/modules/container.py", line 139, in forward
    input = module(input)
  File "/home/lts5-ts/anaconda3/envs/pycolo/lib/python3.9/site-packages/torch/nn/modules/module.py", line 1051, in _call_impl
    return forward_call(*input, **kwargs)
  File "/home/lts5-ts/anaconda3/envs/pycolo/lib/python3.9/site-packages/torch/nn/modules/linear.py", line 96, in forward
    return F.linear(input, self.weight, self.bias)
  File "/home/lts5-ts/anaconda3/envs/pycolo/lib/python3.9/site-packages/torch/nn/functional.py", line 1847, in linear
    return torch._C._nn.linear(input, weight, bias)
RuntimeError: CUDA error: CUBLAS_STATUS_INVALID_VALUE when calling `cublasSgemm( handle, opa, opb, m, n, k, &alpha, a, lda, b, ldb, &beta, c, ldc)`